Workbook

Sheet Mucambo
A1: Relatório BackOffice - Central > Movimentação > Transferências > Transferências externas por loja Selecionar a loja e exportar como Xlsx Dados Arquivo | I1: Transferências - Mucambo (Maio/2026) | M1: Total
M3: =SUM(N6:N1048576) -> 46226.957 | P3: 41516.245
A5: Código+Produto | B5: UN | C5: Qtde | D5: Vl. Unitário | E5: Vl. Total | F5: Produto | G5: Grupo | I5: Grupo | J5: Produto | K5: UN | L5: Quantidade | M5: Valor Unitário | N5: Valor Total
A6: 21-CAJUINA SAO GERALDO 1L | B6: UN | C6: 12 | D6: 6.6667 | E6: =TabelaMucambo[[#This Row],[Qtde]]*TabelaMucambo[[#This Row],[Vl. Unitário]] -> 80.0004 | F6: =VLOOKUP(TabelaMucambo[[#This Row],[Código+Produto]],Base!A:C,3,0) -> CAJUINA SAO GERALDO 1L | G6: =VLOOKUP(A6,Base!A:D,4,0) -> REFRIGERANTES | I6: CARNES BOVINAS | J6: contra file mp | K6: KG | L6: 293.396 | M6: 41.77 | N6: 12244.514
A7: 28-COCA-COLA KS 290ML | B7: UN | C7: 24 | D7: 2.6442 | E7: =TabelaMucambo[[#This Row],[Qtde]]*TabelaMucambo[[#This Row],[Vl. Unitário]] -> 63.4608 | F7: =VLOOKUP(TabelaMucambo[[#This Row],[Código+Produto]],Base!A:C,3,0) -> COCA-COLA KS 290ML | G7: =VLOOKUP(A7,Base!A:D,4,0) -> REFRIGERANTES | I7: CARNES BOVINAS | J7: picanha importada mp | K7: KG | L7: 36.82 | M7: 92.886218 | N7: 3417.1316
A8: 293-MOUSSE DE MARACUJA | B8: UN | C8: 10 | D8: 6 | E8: =TabelaMucambo[[#This Row],[Qtde]]*TabelaMucambo[[#This Row],[Vl. Unitário]] -> 60 | F8: =VLOOKUP(TabelaMucambo[[#This Row],[Código+Produto]],Base!A:C,3,0) -> MOUSSE DE MARACUJA | G8: =VLOOKUP(A8,Base!A:D,4,0) -> MOUSSES | I8: CARNES BOVINAS | J8: file mignon mp | K8: KG | L8: 7.9 | M8: 64.9951 | N8: 513.45786
A9: 296-PUDIM DE LEITE CONDENSADO | B9: UN | C9: 6 | D9: 9 | E9: =TabelaMucambo[[#This Row],[Qtde]]*TabelaMucambo[[#This Row],[Vl. Unitário]] -> 54 | F9: =VLOOKUP(TabelaMucambo[[#This Row],[Código+Produto]],Base!A:C,3,0) -> PUDIM DE LEITE CONDENSADO | G9: =VLOOKUP(A9,Base!A:D,4,0) -> PUDINS | I9: CARNES BOVINAS | J9: carne de sol mp | K9: KG | L9: 2 | M9: 46.9067 | N9: 93.8134
A10: 318-QUENTINHA DE ISOPOR | B10: SC100 | C10: 1 | D10: 0.32 | E10: =TabelaMucambo[[#This Row],[Qtde]]*TabelaMucambo[[#This Row],[Vl. Unitário]] -> 0.32 | F10: =VLOOKUP(TabelaMucambo[[#This Row],[Código+Produto]],Base!A:C,3,0) -> QUENTINHA DE ISOPOR | G10: =VLOOKUP(A10,Base!A:D,4,0) -> EMBALAGENS
A11: 318-QUENTINHA DE ISOPOR | B11: SC100 | C11: 2 | D11: 0.32 | E11: =TabelaMucambo[[#This Row],[Qtde]]*TabelaMucambo[[#This Row],[Vl. Unitário]] -> 0.64 | F11: =VLOOKUP(TabelaMucambo[[#This Row],[Código+Produto]],Base!A:C,3,0) -> QUENTINHA DE ISOPOR | G11: =VLOOKUP(A11,Base!A:D,4,0) -> EMBALAGENS | I11: FRANGOS E DERIVADOS | J11: file de peito de frango mp | K11: KG | L11: 259.626 | M11: 16.674429 | N11: 4344.3195
A12: 429-carne de sol mp | B12: KG | C12: 2 | D12: 46.9067 | E12: =TabelaMucambo[[#This Row],[Qtde]]*TabelaMucambo[[#This Row],[Vl. Unitário]] -> 93.8134 | F12: =VLOOKUP(TabelaMucambo[[#This Row],[Código+Produto]],Base!A:C,3,0) -> carne de sol mp | G12: =VLOOKUP(A12,Base!A:D,4,0) -> CARNES BOVINAS | I12: FRANGOS E DERIVADOS | J12: ovo mp | K12: UN | L12: 690 | M12: 0.5667 | N12: 391.023
A13: 430-contra file mp | B13: KG | C13: 14.4 | D13: 42.89 | E13: =TabelaMucambo[[#This Row],[Qtde]]*TabelaMucambo[[#This Row],[Vl. Unitário]] -> 617.616 | F13: =VLOOKUP(TabelaMucambo[[#This Row],[Código+Produto]],Base!A:C,3,0) -> contra file mp | G13: =VLOOKUP(A13,Base!A:D,4,0) -> CARNES BOVINAS | I13: FRANGOS E DERIVADOS | J13: ovo mp | K13: BJ30 | L13: 10 | M13: 17.001 | N13: 170.01
A14: 430-contra file mp | B14: KG | C14: 19.6 | D14: 42.89 | E14: =TabelaMucambo[[#This Row],[Qtde]]*TabelaMucambo[[#This Row],[Vl. Unitário]] -> 840.644 | F14: =VLOOKUP(TabelaMucambo[[#This Row],[Código+Produto]],Base!A:C,3,0) -> contra file mp | G14: =VLOOKUP(A14,Base!A:D,4,0) -> CARNES BOVINAS | I14: FRANGOS E DERIVADOS | J14: frango inteiro mp | K14: KG | L14: 10.6 | M14: 9.9708 | N14: 105.69048
A15: 430-contra file mp | B15: KG | C15: 10.25 | D15: 42.89 | E15: =TabelaMucambo[[#This Row],[Qtde]]*TabelaMucambo[[#This Row],[Vl. Unitário]] -> 439.6225 | F15: =VLOOKUP(TabelaMucambo[[#This Row],[Código+Produto]],Base!A:C,3,0) -> contra file mp | G15: =VLOOKUP(A15,Base!A:D,4,0) -> CARNES BOVINAS
A16: 430-contra file mp | B16: KG | C16: 43 | D16: 42.89 | E16: =TabelaMucambo[[#This Row],[Qtde]]*TabelaMucambo[[#This Row],[Vl. Unitário]] -> 1844.27 | F16: =VLOOKUP(TabelaMucambo[[#This Row],[Código+Produto]],Base!A:C,3,0) -> contra file mp | G16: =VLOOKUP(A16,Base!A:D,4,0) -> CARNES BOVINAS | I16: SUINOS E DERIVADOS | J16: carne suina mp | K16: KG | L16: 189.6 | M16: 16.5701 | N16: 3141.691
A17: 430-contra file mp | B17: KG | C17: 21.25 | D17: 42.89 | E17: =TabelaMucambo[[#This Row],[Qtde]]*TabelaMucambo[[#This Row],[Vl. Unitário]] -> 911.4125 | F17: =VLOOKUP(TabelaMucambo[[#This Row],[Código+Produto]],Base!A:C,3,0) -> contra file mp | G17: =VLOOKUP(A17,Base!A:D,4,0) -> CARNES BOVINAS | I17: SUINOS E DERIVADOS | J17: bacon mp | K17: KG | L17: 32.718 | M17: 23.668643 | N17: 772.08503
A18: 430-contra file mp | B18: KG | C18: 22.886 | D18: 42.89 | E18: =TabelaMucambo[[#This Row],[Qtde]]*TabelaMucambo[[#This Row],[Vl. Unitário]] -> 981.58054 | F18: =VLOOKUP(TabelaMucambo[[#This Row],[Código+Produto]],Base!A:C,3,0) -> contra file mp | G18: =VLOOKUP(A18,Base!A:D,4,0) -> CARNES BOVINAS | I18: SUINOS E DERIVADOS | J18: costela suina mp | K18: KG | L18: 8.25 | M18: 19.68485 | N18: 162.21642
A19: 430-contra file mp | B19: KG | C19: 22.46 | D19: 41.89 | E19: =TabelaMucambo[[#This Row],[Qtde]]*TabelaMucambo[[#This Row],[Vl. Unitário]] -> 940.8494 | F19: =VLOOKUP(TabelaMucambo[[#This Row],[Código+Produto]],Base!A:C,3,0) -> contra file mp | G19: =VLOOKUP(A19,Base!A:D,4,0) -> CARNES BOVINAS
A20: 430-contra file mp | B20: KG | C20: 24.34 | D20: 41.89 | E20: =TabelaMucambo[[#This Row],[Qtde]]*TabelaMucambo[[#This Row],[Vl. Unitário]] -> 1019.6026 | F20: =VLOOKUP(TabelaMucambo[[#This Row],[Código+Produto]],Base!A:C,3,0) -> contra file mp | G20: =VLOOKUP(A20,Base!A:D,4,0) -> CARNES BOVINAS | I20: HORTIFRUTI | J20: tomate mp | K20: KG | L20: 175.9 | M20: 7 | N20: 1231.3
A21: 430-contra file mp | B21: KG | C21: 19.774 | D21: 41 | E21: =TabelaMucambo[[#This Row],[Qtde]]*TabelaMucambo[[#This Row],[Vl. Unitário]] -> 810.734 | F21: =VLOOKUP(TabelaMucambo[[#This Row],[Código+Produto]],Base!A:C,3,0) -> contra file mp | G21: =VLOOKUP(A21,Base!A:D,4,0) -> CARNES BOVINAS | I21: HORTIFRUTI | J21: laranja mp | K21: KG | L21: 280.05 | M21: 2.1053 | N21: 589.58927
A22: 430-contra file mp | B22: KG | C22: 24.926 | D22: 41 | E22: =TabelaMucambo[[#This Row],[Qtde]]*TabelaMucambo[[#This Row],[Vl. Unitário]] -> 1021.966 | F22: =VLOOKUP(TabelaMucambo[[#This Row],[Código+Produto]],Base!A:C,3,0) -> contra file mp | G22: =VLOOKUP(A22,Base!A:D,4,0) -> CARNES BOVINAS | I22: HORTIFRUTI | J22: batata inglesa mp | K22: KG | L22: 188.2 | M22: 2.7083 | N22: 509.70206
A23: 430-contra file mp | B23: KG | C23: 23.64 | D23: 41 | E23: =TabelaMucambo[[#This Row],[Qtde]]*TabelaMucambo[[#This Row],[Vl. Unitário]] -> 969.24 | F23: =VLOOKUP(TabelaMucambo[[#This Row],[Código+Produto]],Base!A:C,3,0) -> contra file mp | G23: =VLOOKUP(A23,Base!A:D,4,0) -> CARNES BOVINAS | I23: HORTIFRUTI | J23: cenoura mp | K23: KG | L23: 117.89 | M23: 2.75 | N23: 319.8
A24: 430-contra file mp | B24: KG | C24: 21.4 | D24: 39.89 | E24: =TabelaMucambo[[#This Row],[Qtde]]*TabelaMucambo[[#This Row],[Vl. Unitário]] -> 853.646 | F24: =VLOOKUP(TabelaMucambo[[#This Row],[Código+Produto]],Base!A:C,3,0) -> contra file mp | G24: =VLOOKUP(A24,Base!A:D,4,0) -> CARNES BOVINAS | I24: HORTIFRUTI | J24: cebola branca mp | K24: KG | L24: 110.5 | M24: 1.7 | N24: 187.85
A25: 430-contra file mp | B25: KG | C25: 25.47 | D25: 39 | E25: =TabelaMucambo[[#This Row],[Qtde]]*TabelaMucambo[[#This Row],[Vl. Unitário]] -> 993.33 | F25: =VLOOKUP(TabelaMucambo[[#This Row],[Código+Produto]],Base!A:C,3,0) -> contra file mp | G25: =VLOOKUP(A25,Base!A:D,4,0) -> CARNES BOVINAS | I25: HORTIFRUTI | J25: pimentao mp | K25: KG | L25: 42.94 | M25: 2.75 | N25: 120.675
A26: 432-file mignon mp | B26: KG | C26: 3.6 | D26: 65 | E26: =TabelaMucambo[[#This Row],[Qtde]]*TabelaMucambo[[#This Row],[Vl. Unitário]] -> 234 | F26: =VLOOKUP(TabelaMucambo[[#This Row],[Código+Produto]],Base!A:C,3,0) -> file mignon mp | G26: =VLOOKUP(A26,Base!A:D,4,0) -> CARNES BOVINAS | I26: HORTIFRUTI | J26: abacaxi mp | K26: UN | L26: 27 | M26: 3.6111 | N26: 97.4997
A27: 432-file mignon mp | B27: KG | C27: 4.3 | D27: 64.9902 | E27: =TabelaMucambo[[#This Row],[Qtde]]*TabelaMucambo[[#This Row],[Vl. Unitário]] -> 279.45786 | F27: =VLOOKUP(TabelaMucambo[[#This Row],[Código+Produto]],Base!A:C,3,0) -> file mignon mp | G27: =VLOOKUP(A27,Base!A:D,4,0) -> CARNES BOVINAS | I27: HORTIFRUTI | J27: alho mp | K27: KG | L27: 10.6 | M27: 8 | N27: 84.8
A28: 434-picanha importada mp | B28: KG | C28: 8.5 | D28: 92.1704 | E28: =TabelaMucambo[[#This Row],[Qtde]]*TabelaMucambo[[#This Row],[Vl. Unitário]] -> 783.4484 | F28: =VLOOKUP(TabelaMucambo[[#This Row],[Código+Produto]],Base!A:C,3,0) -> picanha importada mp | G28: =VLOOKUP(A28,Base!A:D,4,0) -> CARNES BOVINAS | I28: HORTIFRUTI | J28: brocolis mp | K28: KG | L28: 11.08 | M28: 6.2868 | N28: 69.657744
A29: 434-picanha importada mp | B29: KG | C29: 2.55 | D29: 92.1704 | E29: =TabelaMucambo[[#This Row],[Qtde]]*TabelaMucambo[[#This Row],[Vl. Unitário]] -> 235.03452 | F29: =VLOOKUP(TabelaMucambo[[#This Row],[Código+Produto]],Base!A:C,3,0) -> picanha importada mp | G29: =VLOOKUP(A29,Base!A:D,4,0) -> CARNES BOVINAS | I29: HORTIFRUTI | J29: morango mp | K29: KG | L29: 2.05 | M29: 27.5 | N29: 54.5
A30: 434-picanha importada mp | B30: KG | C30: 3.3 | D30: 92.168 | E30: =TabelaMucambo[[#This Row],[Qtde]]*TabelaMucambo[[#This Row],[Vl. Unitário]] -> 304.1544 | F30: =VLOOKUP(TabelaMucambo[[#This Row],[Código+Produto]],Base!A:C,3,0) -> picanha importada mp | G30: =VLOOKUP(A30,Base!A:D,4,0) -> CARNES BOVINAS | I30: HORTIFRUTI | J30: limao mp | K30: KG | L30: 8.2 | M30: 4 | N30: 32.8
A31: 434-picanha importada mp | B31: KG | C31: 3.25 | D31: 92.168 | E31: =TabelaMucambo[[#This Row],[Qtde]]*TabelaMucambo[[#This Row],[Vl. Unitário]] -> 299.546 | F31: =VLOOKUP(TabelaMucambo[[#This Row],[Código+Produto]],Base!A:C,3,0) -> picanha importada mp | G31: =VLOOKUP(A31,Base!A:D,4,0) -> CARNES BOVINAS | I31: HORTIFRUTI | J31: coentro mp | K31: KG | L31: 14.9 | M31: 1.55 | N31: 23.095
... A34: 434-picanha importada mp | B34: KG | C34: 3.15 | D34: 96.0489 | E34: =TabelaMucambo[[#This Row],[Qtde]]*TabelaMucambo[[#This Row],[Vl. Unitário]] -> 302.55403 | F34: =VLOOKUP(TabelaMucambo[[#This Row],[Código+Produto]],Base!A:C,3,0) -> picanha importada mp | G34: =VLOOKUP(A34,Base!A:D,4,0) -> CARNES BOVINAS | I34: HORTIFRUTI | J34: alface mp | K34: KG | L34: 6.67 | M34: 0.75 | N34: 5.0025
A35: 434-picanha importada mp | B35: KG | C35: 3 | D35: 92.168 | E35: =TabelaMucambo[[#This Row],[Qtde]]*TabelaMucambo[[#This Row],[Vl. Unitário]] -> 276.504 | F35: =VLOOKUP(TabelaMucambo[[#This Row],[Código+Produto]],Base!A:C,3,0) -> picanha importada mp | G35: =VLOOKUP(A35,Base!A:D,4,0) -> CARNES BOVINAS
A36: 434-picanha importada mp | B36: KG | C36: 1.85 | D36: 93.3642 | E36: =TabelaMucambo[[#This Row],[Qtde]]*TabelaMucambo[[#This Row],[Vl. Unitário]] -> 172.72377 | F36: =VLOOKUP(TabelaMucambo[[#This Row],[Código+Produto]],Base!A:C,3,0) -> picanha importada mp | G36: =VLOOKUP(A36,Base!A:D,4,0) -> CARNES BOVINAS | I36: SECOS E MERCEARIA | J36: maionese mp | K36: KG | L36: 104.25 | M36: 10.730283 | N36: 1118.7853
A37: 434-picanha importada mp | B37: KG | C37: 2.7 | D37: 93.0899 | E37: =TabelaMucambo[[#This Row],[Qtde]]*TabelaMucambo[[#This Row],[Vl. Unitário]] -> 251.34273 | F37: =VLOOKUP(TabelaMucambo[[#This Row],[Código+Produto]],Base!A:C,3,0) -> picanha importada mp | G37: =VLOOKUP(A37,Base!A:D,4,0) -> CARNES BOVINAS | I37: SECOS E MERCEARIA | J37: arroz parboilizado mp | K37: KG | L37: 280 | M37: 3.8045455 | N37: 1065
A38: 434-picanha importada mp | B38: KG | C38: 4.57 | D38: 93.0899 | E38: =TabelaMucambo[[#This Row],[Qtde]]*TabelaMucambo[[#This Row],[Vl. Unitário]] -> 425.42084 | F38: =VLOOKUP(TabelaMucambo[[#This Row],[Código+Produto]],Base!A:C,3,0) -> picanha importada mp | G38: =VLOOKUP(A38,Base!A:D,4,0) -> CARNES BOVINAS | I38: SECOS E MERCEARIA | J38: arroz branco mp | K38: KG | L38: 40 | M38: 4.57 | N38: 182.8
A39: 436-batata pre frita mp | B39: KG | C39: 12 | D39: 12.9543 | E39: =TabelaMucambo[[#This Row],[Qtde]]*TabelaMucambo[[#This Row],[Vl. Unitário]] -> 155.4516 | F39: =VLOOKUP(TabelaMucambo[[#This Row],[Código+Produto]],Base!A:C,3,0) -> batata pre frita mp | G39: =VLOOKUP(A39,Base!A:D,4,0) -> CONGELADOS | I39: SECOS E MERCEARIA | J39: creme culinario mp | K39: KG | L39: 13 | M39: 12.634733 | N39: 165.3897
A40: 436-batata pre frita mp | B40: KG | C40: 24 | D40: 12.9543 | E40: =TabelaMucambo[[#This Row],[Qtde]]*TabelaMucambo[[#This Row],[Vl. Unitário]] -> 310.9032 | F40: =VLOOKUP(TabelaMucambo[[#This Row],[Código+Produto]],Base!A:C,3,0) -> batata pre frita mp | G40: =VLOOKUP(A40,Base!A:D,4,0) -> CONGELADOS | I40: SECOS E MERCEARIA | J40: farinha de rosca mp | K40: KG | L40: 22.4 | M40: 7 | N40: 156.8
A41: 436-batata pre frita mp | B41: KG | C41: 12 | D41: 12.9543 | E41: =TabelaMucambo[[#This Row],[Qtde]]*TabelaMucambo[[#This Row],[Vl. Unitário]] -> 155.4516 | F41: =VLOOKUP(TabelaMucambo[[#This Row],[Código+Produto]],Base!A:C,3,0) -> batata pre frita mp | G41: =VLOOKUP(A41,Base!A:D,4,0) -> CONGELADOS | I41: SECOS E MERCEARIA | J41: macarrao espaguete mp | K41: 400G | L41: 28 | M41: 2.99 | N41: 83.72
A42: 436-batata pre frita mp | B42: KG | C42: 12 | D42: 12.9543 | E42: =TabelaMucambo[[#This Row],[Qtde]]*TabelaMucambo[[#This Row],[Vl. Unitário]] -> 155.4516 | F42: =VLOOKUP(TabelaMucambo[[#This Row],[Código+Produto]],Base!A:C,3,0) -> batata pre frita mp | G42: =VLOOKUP(A42,Base!A:D,4,0) -> CONGELADOS | I42: SECOS E MERCEARIA | J42: macarrao espaguete mp | K42: KG | L42: 5.7 | M42: 7.475 | N42: 42.6075
A43: 436-batata pre frita mp | B43: KG | C43: 12 | D43: 12.9543 | E43: =TabelaMucambo[[#This Row],[Qtde]]*TabelaMucambo[[#This Row],[Vl. Unitário]] -> 155.4516 | F43: =VLOOKUP(TabelaMucambo[[#This Row],[Código+Produto]],Base!A:C,3,0) -> batata pre frita mp | G43: =VLOOKUP(A43,Base!A:D,4,0) -> CONGELADOS | I43: SECOS E MERCEARIA | J43: farinha de trigo mp | K43: KG | L43: 30 | M43: 3.94 | N43: 118.2
A44: 436-batata pre frita mp | B44: KG | C44: 24 | D44: 12.9539 | E44: =TabelaMucambo[[#This Row],[Qtde]]*TabelaMucambo[[#This Row],[Vl. Unitário]] -> 310.8936 | F44: =VLOOKUP(TabelaMucambo[[#This Row],[Código+Produto]],Base!A:C,3,0) -> batata pre frita mp | G44: =VLOOKUP(A44,Base!A:D,4,0) -> CONGELADOS | I44: SECOS E MERCEARIA | J44: feijao branco mp | K44: KG | L44: 11.5 | M44: 6.5 | N44: 74.75
...

Sheet Frecheirinha
A1: Relatório BackOffice - Central > Movimentação > Transferências > Transferências externas por loja Selecionar a loja e exportar como Xlsx Dados Arquivo | I1: Transferências - Frecheirinha (Maio/2026) | M1: Total
M3: =SUM(N6:N1048576) -> 55885.84 | P3: 39621.933
A5: Código+Produto | B5: UN | C5: Qtde | D5: Vl. Unitário | E5: Vl. Total | F5: Produto | G5: Grupo | I5: Grupo | J5: Produto | K5: UN | L5: Quantidade | M5: Valor Unitário | N5: Valor Total
A6: 1090-capa de contra file mp | B6: KG | C6: 13.3 | D6: 30.6301 | E6: =TabelaFrecheirinha[[#This Row],[Qtde]]*TabelaFrecheirinha[[#This Row],[Vl. Unitário]] -> 407.38033 | F6: =VLOOKUP(TabelaFrecheirinha[[#This Row],[Código+Produto]],Base!A:C,3,0) -> capa de contra file mp | G6: =VLOOKUP(A6,Base!A:D,4,0) -> CARNES BOVINAS | I6: CARNES BOVINAS | J6: contra file mp | K6: KG | L6: 305 | M6: 41.534 | N6: 12708.758
A7: 296-PUDIM DE LEITE CONDENSADO | B7: UN | C7: 12 | D7: 9 | E7: =TabelaFrecheirinha[[#This Row],[Qtde]]*TabelaFrecheirinha[[#This Row],[Vl. Unitário]] -> 108 | F7: =VLOOKUP(TabelaFrecheirinha[[#This Row],[Código+Produto]],Base!A:C,3,0) -> PUDIM DE LEITE CONDENSADO | G7: =VLOOKUP(A7,Base!A:D,4,0) -> PUDINS | I7: CARNES BOVINAS | J7: picanha importada mp | K7: KG | L7: 29.55 | M7: 92.17448 | N7: 2723.7281
A8: 429-carne de sol mp | B8: KG | C8: 3.8 | D8: 46.9067 | E8: =TabelaFrecheirinha[[#This Row],[Qtde]]*TabelaFrecheirinha[[#This Row],[Vl. Unitário]] -> 178.24546 | F8: =VLOOKUP(TabelaFrecheirinha[[#This Row],[Código+Produto]],Base!A:C,3,0) -> carne de sol mp | G8: =VLOOKUP(A8,Base!A:D,4,0) -> CARNES BOVINAS | I8: CARNES BOVINAS | J8: file mignon mp | K8: KG | L8: 27.95 | M8: 64.99755 | N8: 1816.6892
A9: 429-carne de sol mp | B9: KG | C9: 3.1 | D9: 46.9067 | E9: =TabelaFrecheirinha[[#This Row],[Qtde]]*TabelaFrecheirinha[[#This Row],[Vl. Unitário]] -> 145.41077 | F9: =VLOOKUP(TabelaFrecheirinha[[#This Row],[Código+Produto]],Base!A:C,3,0) -> carne de sol mp | G9: =VLOOKUP(A9,Base!A:D,4,0) -> CARNES BOVINAS | I9: CARNES BOVINAS | J9: costela bovina mp | K9: KG | L9: 20.9 | M9: 19.5 | N9: 407.55
A10: 430-contra file mp | B10: KG | C10: 25.5 | D10: 42.89 | E10: =TabelaFrecheirinha[[#This Row],[Qtde]]*TabelaFrecheirinha[[#This Row],[Vl. Unitário]] -> 1093.695 | F10: =VLOOKUP(TabelaFrecheirinha[[#This Row],[Código+Produto]],Base!A:C,3,0) -> contra file mp | G10: =VLOOKUP(A10,Base!A:D,4,0) -> CARNES BOVINAS | I10: CARNES BOVINAS | J10: capa de contra file mp | K10: KG | L10: 13.3 | M10: 30.6301 | N10: 407.38033
A11: 430-contra file mp | B11: KG | C11: 58 | D11: 42.89 | E11: =TabelaFrecheirinha[[#This Row],[Qtde]]*TabelaFrecheirinha[[#This Row],[Vl. Unitário]] -> 2487.62 | F11: =VLOOKUP(TabelaFrecheirinha[[#This Row],[Código+Produto]],Base!A:C,3,0) -> contra file mp | G11: =VLOOKUP(A11,Base!A:D,4,0) -> CARNES BOVINAS | I11: CARNES BOVINAS | J11: carne de sol mp | K11: KG | L11: 6.9 | M11: 46.9067 | N11: 323.65623
A12: 430-contra file mp | B12: KG | C12: 25.9 | D12: 42.89 | E12: =TabelaFrecheirinha[[#This Row],[Qtde]]*TabelaFrecheirinha[[#This Row],[Vl. Unitário]] -> 1110.851 | F12: =VLOOKUP(TabelaFrecheirinha[[#This Row],[Código+Produto]],Base!A:C,3,0) -> contra file mp | G12: =VLOOKUP(A12,Base!A:D,4,0) -> CARNES BOVINAS | I12: CARNES BOVINAS | J12: cordao do file mignon mp | K12: KG | L12: 5 | M12: 26.4999 | N12: 132.4995
A13: 430-contra file mp | B13: KG | C13: 27.95 | D13: 42.89 | E13: =TabelaFrecheirinha[[#This Row],[Qtde]]*TabelaFrecheirinha[[#This Row],[Vl. Unitário]] -> 1198.7755 | F13: =VLOOKUP(TabelaFrecheirinha[[#This Row],[Código+Produto]],Base!A:C,3,0) -> contra file mp | G13: =VLOOKUP(A13,Base!A:D,4,0) -> CARNES BOVINAS
A14: 430-contra file mp | B14: KG | C14: 27 | D14: 41 | E14: =TabelaFrecheirinha[[#This Row],[Qtde]]*TabelaFrecheirinha[[#This Row],[Vl. Unitário]] -> 1107 | F14: =VLOOKUP(TabelaFrecheirinha[[#This Row],[Código+Produto]],Base!A:C,3,0) -> contra file mp | G14: =VLOOKUP(A14,Base!A:D,4,0) -> CARNES BOVINAS | I14: PEIXES E FRUTOS DO MAR | J14: tilapia limpa mp | K14: KG | L14: 370.55 | M14: 17 | N14: 6299.35
A15: 430-contra file mp | B15: KG | C15: 15.85 | D15: 41 | E15: =TabelaFrecheirinha[[#This Row],[Qtde]]*TabelaFrecheirinha[[#This Row],[Vl. Unitário]] -> 649.85 | F15: =VLOOKUP(TabelaFrecheirinha[[#This Row],[Código+Produto]],Base!A:C,3,0) -> contra file mp | G15: =VLOOKUP(A15,Base!A:D,4,0) -> CARNES BOVINAS | I15: PEIXES E FRUTOS DO MAR | J15: camarao mp | K15: KG | L15: 30.1 | M15: 33 | N15: 993.3
A16: 430-contra file mp | B16: KG | C16: 24 | D16: 41 | E16: =TabelaFrecheirinha[[#This Row],[Qtde]]*TabelaFrecheirinha[[#This Row],[Vl. Unitário]] -> 984 | F16: =VLOOKUP(TabelaFrecheirinha[[#This Row],[Código+Produto]],Base!A:C,3,0) -> contra file mp | G16: =VLOOKUP(A16,Base!A:D,4,0) -> CARNES BOVINAS
A17: 430-contra file mp | B17: KG | C17: 50.5 | D17: 41 | E17: =TabelaFrecheirinha[[#This Row],[Qtde]]*TabelaFrecheirinha[[#This Row],[Vl. Unitário]] -> 2070.5 | F17: =VLOOKUP(TabelaFrecheirinha[[#This Row],[Código+Produto]],Base!A:C,3,0) -> contra file mp | G17: =VLOOKUP(A17,Base!A:D,4,0) -> CARNES BOVINAS | I17: SUINOS E DERIVADOS | J17: carne suina mp | K17: KG | L17: 269.6 | M17: 16.5701 | N17: 4467.299
A18: 430-contra file mp | B18: KG | C18: 24 | D18: 39.89 | E18: =TabelaFrecheirinha[[#This Row],[Qtde]]*TabelaFrecheirinha[[#This Row],[Vl. Unitário]] -> 957.36 | F18: =VLOOKUP(TabelaFrecheirinha[[#This Row],[Código+Produto]],Base!A:C,3,0) -> contra file mp | G18: =VLOOKUP(A18,Base!A:D,4,0) -> CARNES BOVINAS | I18: SUINOS E DERIVADOS | J18: costela suina mp | K18: KG | L18: 33.55 | M18: 19.51 | N18: 654.5605
A19: 430-contra file mp | B19: KG | C19: 26.3 | D19: 39.89 | E19: =TabelaFrecheirinha[[#This Row],[Qtde]]*TabelaFrecheirinha[[#This Row],[Vl. Unitário]] -> 1049.107 | F19: =VLOOKUP(TabelaFrecheirinha[[#This Row],[Código+Produto]],Base!A:C,3,0) -> contra file mp | G19: =VLOOKUP(A19,Base!A:D,4,0) -> CARNES BOVINAS | I19: SUINOS E DERIVADOS | J19: bacon mp | K19: KG | L19: 22.4 | M19: 23.6714 | N19: 531.07136
A20: 431-cordao do file mignon mp | B20: KG | C20: 5 | D20: 26.4999 | E20: =TabelaFrecheirinha[[#This Row],[Qtde]]*TabelaFrecheirinha[[#This Row],[Vl. Unitário]] -> 132.4995 | F20: =VLOOKUP(TabelaFrecheirinha[[#This Row],[Código+Produto]],Base!A:C,3,0) -> cordao do file mignon mp | G20: =VLOOKUP(A20,Base!A:D,4,0) -> CARNES BOVINAS
A21: 432-file mignon mp | B21: KG | C21: 3.25 | D21: 65 | E21: =TabelaFrecheirinha[[#This Row],[Qtde]]*TabelaFrecheirinha[[#This Row],[Vl. Unitário]] -> 211.25 | F21: =VLOOKUP(TabelaFrecheirinha[[#This Row],[Código+Produto]],Base!A:C,3,0) -> file mignon mp | G21: =VLOOKUP(A21,Base!A:D,4,0) -> CARNES BOVINAS | I21: FRANGOS E DERIVADOS | J21: file de peito de frango mp | K21: KG | L21: 210 | M21: 17.127 | N21: 3618.27
A22: 432-file mignon mp | B22: KG | C22: 5.35 | D22: 65 | E22: =TabelaFrecheirinha[[#This Row],[Qtde]]*TabelaFrecheirinha[[#This Row],[Vl. Unitário]] -> 347.75 | F22: =VLOOKUP(TabelaFrecheirinha[[#This Row],[Código+Produto]],Base!A:C,3,0) -> file mignon mp | G22: =VLOOKUP(A22,Base!A:D,4,0) -> CARNES BOVINAS | I22: FRANGOS E DERIVADOS | J22: frango inteiro mp | K22: KG | L22: 76.5 | M22: 9.9708 | N22: 762.7662
A23: 432-file mignon mp | B23: KG | C23: 4 | D23: 65 | E23: =TabelaFrecheirinha[[#This Row],[Qtde]]*TabelaFrecheirinha[[#This Row],[Vl. Unitário]] -> 260 | F23: =VLOOKUP(TabelaFrecheirinha[[#This Row],[Código+Produto]],Base!A:C,3,0) -> file mignon mp | G23: =VLOOKUP(A23,Base!A:D,4,0) -> CARNES BOVINAS | I23: FRANGOS E DERIVADOS | J23: coxa e sobrecoxa mp | K23: KG | L23: 22.55 | M23: 8.9932333 | N23: 203.96965
A24: 432-file mignon mp | B24: KG | C24: 1.25 | D24: 64.9902 | E24: =TabelaFrecheirinha[[#This Row],[Qtde]]*TabelaFrecheirinha[[#This Row],[Vl. Unitário]] -> 81.23775 | F24: =VLOOKUP(TabelaFrecheirinha[[#This Row],[Código+Produto]],Base!A:C,3,0) -> file mignon mp | G24: =VLOOKUP(A24,Base!A:D,4,0) -> CARNES BOVINAS
A25: 432-file mignon mp | B25: KG | C25: 4.95 | D25: 64.9902 | E25: =TabelaFrecheirinha[[#This Row],[Qtde]]*TabelaFrecheirinha[[#This Row],[Vl. Unitário]] -> 321.70149 | F25: =VLOOKUP(TabelaFrecheirinha[[#This Row],[Código+Produto]],Base!A:C,3,0) -> file mignon mp | G25: =VLOOKUP(A25,Base!A:D,4,0) -> CARNES BOVINAS | I25: CONGELADOS | J25: batata pre frita mp | K25: KG | L25: 304 | M25: 12.413685 | N25: 3764.8152
A26: 432-file mignon mp | B26: KG | C26: 3.85 | D26: 65 | E26: =TabelaFrecheirinha[[#This Row],[Qtde]]*TabelaFrecheirinha[[#This Row],[Vl. Unitário]] -> 250.25 | F26: =VLOOKUP(TabelaFrecheirinha[[#This Row],[Código+Produto]],Base!A:C,3,0) -> file mignon mp | G26: =VLOOKUP(A26,Base!A:D,4,0) -> CARNES BOVINAS
A27: 432-file mignon mp | B27: KG | C27: 1.6 | D27: 65 | E27: =TabelaFrecheirinha[[#This Row],[Qtde]]*TabelaFrecheirinha[[#This Row],[Vl. Unitário]] -> 104 | F27: =VLOOKUP(TabelaFrecheirinha[[#This Row],[Código+Produto]],Base!A:C,3,0) -> file mignon mp | G27: =VLOOKUP(A27,Base!A:D,4,0) -> CARNES BOVINAS | I27: LATICINIOS | J27: leite mp | K27: LT | L27: 325 | M27: 3.5 | N27: 1137.5
A28: 432-file mignon mp | B28: KG | C28: 3.7 | D28: 65 | E28: =TabelaFrecheirinha[[#This Row],[Qtde]]*TabelaFrecheirinha[[#This Row],[Vl. Unitário]] -> 240.5 | F28: =VLOOKUP(TabelaFrecheirinha[[#This Row],[Código+Produto]],Base!A:C,3,0) -> file mignon mp | G28: =VLOOKUP(A28,Base!A:D,4,0) -> CARNES BOVINAS | I28: LATICINIOS | J28: queijo mussarela mp | K28: KG | L28: 32.1 | M28: 31.24505 | N28: 1003.374
A29: 434-picanha importada mp | B29: KG | C29: 4.9 | D29: 92.198 | E29: =TabelaFrecheirinha[[#This Row],[Qtde]]*TabelaFrecheirinha[[#This Row],[Vl. Unitário]] -> 451.7702 | F29: =VLOOKUP(TabelaFrecheirinha[[#This Row],[Código+Produto]],Base!A:C,3,0) -> picanha importada mp | G29: =VLOOKUP(A29,Base!A:D,4,0) -> CARNES BOVINAS | I29: LATICINIOS | J29: queijo coalho mp | K29: KG | L29: 38 | M29: 22.236655 | N29: 839.95175
A30: 434-picanha importada mp | B30: KG | C30: 6.95 | D30: 92.1704 | E30: =TabelaFrecheirinha[[#This Row],[Qtde]]*TabelaFrecheirinha[[#This Row],[Vl. Unitário]] -> 640.58428 | F30: =VLOOKUP(TabelaFrecheirinha[[#This Row],[Código+Produto]],Base!A:C,3,0) -> picanha importada mp | G30: =VLOOKUP(A30,Base!A:D,4,0) -> CARNES BOVINAS | I30: LATICINIOS | J30: margarina mp | K30: KG | L30: 29 | M30: 8.35 | N30: 241.89
A31: 434-picanha importada mp | B31: KG | C31: 7 | D31: 92.168 | E31: =TabelaFrecheirinha[[#This Row],[Qtde]]*TabelaFrecheirinha[[#This Row],[Vl. Unitário]] -> 645.176 | F31: =VLOOKUP(TabelaFrecheirinha[[#This Row],[Código+Produto]],Base!A:C,3,0) -> picanha importada mp | G31: =VLOOKUP(A31,Base!A:D,4,0) -> CARNES BOVINAS
A32: 434-picanha importada mp | B32: KG | C32: 3.7 | D32: 92.168 | E32: =TabelaFrecheirinha[[#This Row],[Qtde]]*TabelaFrecheirinha[[#This Row],[Vl. Unitário]] -> 341.0216 | F32: =VLOOKUP(TabelaFrecheirinha[[#This Row],[Código+Produto]],Base!A:C,3,0) -> picanha importada mp | G32: =VLOOKUP(A32,Base!A:D,4,0) -> CARNES BOVINAS | I32: HORTIFRUTI | J32: tomate mp | K32: KG | L32: 191.95 | M32: 7 | N32: 1343.65
A33: 434-picanha importada mp | B33: KG | C33: 7 | D33: 92.168 | E33: =TabelaFrecheirinha[[#This Row],[Qtde]]*TabelaFrecheirinha[[#This Row],[Vl. Unitário]] -> 645.176 | F33: =VLOOKUP(TabelaFrecheirinha[[#This Row],[Código+Produto]],Base!A:C,3,0) -> picanha importada mp | G33: =VLOOKUP(A33,Base!A:D,4,0) -> CARNES BOVINAS | I33: HORTIFRUTI | J33: laranja mp | K33: KG | L33: 173 | M33: 2.1053 | N33: 364.2169
A34: 436-batata pre frita mp | B34: KG | C34: 24 | D34: 12.9543 | E34: =TabelaFrecheirinha[[#This Row],[Qtde]]*TabelaFrecheirinha[[#This Row],[Vl. Unitário]] -> 310.9032 | F34: =VLOOKUP(TabelaFrecheirinha[[#This Row],[Código+Produto]],Base!A:C,3,0) -> batata pre frita mp | G34: =VLOOKUP(A34,Base!A:D,4,0) -> CONGELADOS | I34: HORTIFRUTI | J34: cenoura mp | K34: KG | L34: 109.83 | M34: 2.8125 | N34: 321.575
A35: 436-batata pre frita mp | B35: KG | C35: 24 | D35: 12.9543 | E35: =TabelaFrecheirinha[[#This Row],[Qtde]]*TabelaFrecheirinha[[#This Row],[Vl. Unitário]] -> 310.9032 | F35: =VLOOKUP(TabelaFrecheirinha[[#This Row],[Código+Produto]],Base!A:C,3,0) -> batata pre frita mp | G35: =VLOOKUP(A35,Base!A:D,4,0) -> CONGELADOS | I35: HORTIFRUTI | J35: batata inglesa mp | K35: KG | L35: 116 | M35: 2.7083 | N35: 314.1628
A36: 436-batata pre frita mp | B36: KG | C36: 12 | D36: 12.9543 | E36: =TabelaFrecheirinha[[#This Row],[Qtde]]*TabelaFrecheirinha[[#This Row],[Vl. Unitário]] -> 155.4516 | F36: =VLOOKUP(TabelaFrecheirinha[[#This Row],[Código+Produto]],Base!A:C,3,0) -> batata pre frita mp | G36: =VLOOKUP(A36,Base!A:D,4,0) -> CONGELADOS | I36: HORTIFRUTI | J36: cebola branca mp | K36: KG | L36: 99.55 | M36: 1.7 | N36: 169.235
A37: 436-batata pre frita mp | B37: KG | C37: 48 | D37: 12.9539 | E37: =TabelaFrecheirinha[[#This Row],[Qtde]]*TabelaFrecheirinha[[#This Row],[Vl. Unitário]] -> 621.7872 | F37: =VLOOKUP(TabelaFrecheirinha[[#This Row],[Código+Produto]],Base!A:C,3,0) -> batata pre frita mp | G37: =VLOOKUP(A37,Base!A:D,4,0) -> CONGELADOS | I37: HORTIFRUTI | J37: limao mp | K37: KG | L37: 35.45 | M37: 4 | N37: 141.8
A38: 436-batata pre frita mp | B38: KG | C38: 24 | D38: 12.9539 | E38: =TabelaFrecheirinha[[#This Row],[Qtde]]*TabelaFrecheirinha[[#This Row],[Vl. Unitário]] -> 310.8936 | F38: =VLOOKUP(TabelaFrecheirinha[[#This Row],[Código+Produto]],Base!A:C,3,0) -> batata pre frita mp | G38: =VLOOKUP(A38,Base!A:D,4,0) -> CONGELADOS | I38: HORTIFRUTI | J38: abacaxi mp | K38: UN | L38: 24 | M38: 3.6111 | N38: 86.6664
A39: 436-batata pre frita mp | B39: KG | C39: 24 | D39: 12.9539 | E39: =TabelaFrecheirinha[[#This Row],[Qtde]]*TabelaFrecheirinha[[#This Row],[Vl. Unitário]] -> 310.8936 | F39: =VLOOKUP(TabelaFrecheirinha[[#This Row],[Código+Produto]],Base!A:C,3,0) -> batata pre frita mp | G39: =VLOOKUP(A39,Base!A:D,4,0) -> CONGELADOS | I39: HORTIFRUTI | J39: pimentao mp | K39: KG | L39: 27.05 | M39: 2.5 | N39: 67.625
A40: 436-batata pre frita mp | B40: KG | C40: 24 | D40: 12.9539 | E40: =TabelaFrecheirinha[[#This Row],[Qtde]]*TabelaFrecheirinha[[#This Row],[Vl. Unitário]] -> 310.8936 | F40: =VLOOKUP(TabelaFrecheirinha[[#This Row],[Código+Produto]],Base!A:C,3,0) -> batata pre frita mp | G40: =VLOOKUP(A40,Base!A:D,4,0) -> CONGELADOS | I40: HORTIFRUTI | J40: alho mp | K40: KG | L40: 7.25 | M40: 8 | N40: 58
A41: 436-batata pre frita mp | B41: KG | C41: 12 | D41: 12.9539 | E41: =TabelaFrecheirinha[[#This Row],[Qtde]]*TabelaFrecheirinha[[#This Row],[Vl. Unitário]] -> 155.4468 | F41: =VLOOKUP(TabelaFrecheirinha[[#This Row],[Código+Produto]],Base!A:C,3,0) -> batata pre frita mp | G41: =VLOOKUP(A41,Base!A:D,4,0) -> CONGELADOS | I41: HORTIFRUTI | J41: morango mp | K41: KG | L41: 1.5 | M41: 35 | N41: 52.5
A42: 436-batata pre frita mp | B42: KG | C42: 24 | D42: 10.5965 | E42: =TabelaFrecheirinha[[#This Row],[Qtde]]*TabelaFrecheirinha[[#This Row],[Vl. Unitário]] -> 254.316 | F42: =VLOOKUP(TabelaFrecheirinha[[#This Row],[Código+Produto]],Base!A:C,3,0) -> batata pre frita mp | G42: =VLOOKUP(A42,Base!A:D,4,0) -> CONGELADOS | I42: HORTIFRUTI | J42: brocolis mp | K42: KG | L42: 7.27 | M42: 6.2868 | N42: 45.705036
...

Sheet Tianguá
A1: Relatório BackOffice - Central > Movimentação > Transferências > Transferências externas por loja Selecionar a loja e exportar como Xlsx Dados Arquivo | I1: Transferências - Tianguá (Maio/2026) | M1: Total
M3: =SUM(N6:N1048576) -> 40751.125 | P3: 35497.706
A5: Código+Produto | B5: UN | C5: Qtde | D5: Vl. Unitário | E5: Vl. Total | F5: Produto | G5: Grupo | I5: Grupo | J5: Produto | K5: UN | L5: Quantidade | M5: Valor Unitário | N5: Valor Total
A6: 1097-lula mp | B6: KG | C6: 1.4 | D6: 15 | E6: =TabelaTianguá[[#This Row],[Qtde]]*TabelaTianguá[[#This Row],[Vl. Unitário]] -> 21 | F6: =VLOOKUP(TabelaTianguá[[#This Row],[Código+Produto]],Base!A:C,3,0) -> #N/A | G6: =VLOOKUP(A6,Base!A:D,4,0) -> #N/A | I6: CARNES BOVINAS | J6: contra file mp | K6: KG | L6: 246.138 | M6: 41.200667 | N6: 10129.948
A7: 1099-peixe pargo mp | B7: KG | C7: 6 | D7: 20 | E7: =TabelaTianguá[[#This Row],[Qtde]]*TabelaTianguá[[#This Row],[Vl. Unitário]] -> 120 | F7: =VLOOKUP(TabelaTianguá[[#This Row],[Código+Produto]],Base!A:C,3,0) -> #N/A | G7: =VLOOKUP(A7,Base!A:D,4,0) -> #N/A | I7: CARNES BOVINAS | J7: picanha importada mp | K7: KG | L7: 57.25 | M7: 93.175573 | N7: 5336.7209
A8: 296-PUDIM DE LEITE CONDENSADO | B8: UN | C8: 10 | D8: 8 | E8: =TabelaTianguá[[#This Row],[Qtde]]*TabelaTianguá[[#This Row],[Vl. Unitário]] -> 80 | F8: =VLOOKUP(TabelaTianguá[[#This Row],[Código+Produto]],Base!A:C,3,0) -> PUDIM DE LEITE CONDENSADO | G8: =VLOOKUP(A8,Base!A:D,4,0) -> PUDINS | I8: CARNES BOVINAS | J8: file mignon mp | K8: KG | L8: 46.35 | M8: 64.996436 | N8: 3012.6344
A9: 296-PUDIM DE LEITE CONDENSADO | B9: UN | C9: 3 | D9: 9 | E9: =TabelaTianguá[[#This Row],[Qtde]]*TabelaTianguá[[#This Row],[Vl. Unitário]] -> 27 | F9: =VLOOKUP(TabelaTianguá[[#This Row],[Código+Produto]],Base!A:C,3,0) -> PUDIM DE LEITE CONDENSADO | G9: =VLOOKUP(A9,Base!A:D,4,0) -> PUDINS | I9: CARNES BOVINAS | J9: carne de sol mp | K9: KG | L9: 7.65 | M9: 46.9067 | N9: 358.83625
A10: 296-PUDIM DE LEITE CONDENSADO | B10: UN | C10: 12 | D10: 9 | E10: =TabelaTianguá[[#This Row],[Qtde]]*TabelaTianguá[[#This Row],[Vl. Unitário]] -> 108 | F10: =VLOOKUP(TabelaTianguá[[#This Row],[Código+Produto]],Base!A:C,3,0) -> PUDIM DE LEITE CONDENSADO | G10: =VLOOKUP(A10,Base!A:D,4,0) -> PUDINS
A11: 296-PUDIM DE LEITE CONDENSADO | B11: UN | C11: 12 | D11: 9 | E11: =TabelaTianguá[[#This Row],[Qtde]]*TabelaTianguá[[#This Row],[Vl. Unitário]] -> 108 | F11: =VLOOKUP(TabelaTianguá[[#This Row],[Código+Produto]],Base!A:C,3,0) -> PUDIM DE LEITE CONDENSADO | G11: =VLOOKUP(A11,Base!A:D,4,0) -> PUDINS | I11: PEIXES E FRUTOS DO MAR | J11: tilapia limpa mp | K11: KG | L11: 107.77 | M11: 17 | N11: 1832.09
A12: 429-carne de sol mp | B12: KG | C12: 2.35 | D12: 46.9067 | E12: =TabelaTianguá[[#This Row],[Qtde]]*TabelaTianguá[[#This Row],[Vl. Unitário]] -> 110.23074 | F12: =VLOOKUP(TabelaTianguá[[#This Row],[Código+Produto]],Base!A:C,3,0) -> carne de sol mp | G12: =VLOOKUP(A12,Base!A:D,4,0) -> CARNES BOVINAS | I12: PEIXES E FRUTOS DO MAR | J12: camarao mp | K12: KG | L12: 46.45 | M12: 32.833333 | N12: 1524.65
A13: 429-carne de sol mp | B13: KG | C13: 1.15 | D13: 46.9067 | E13: =TabelaTianguá[[#This Row],[Qtde]]*TabelaTianguá[[#This Row],[Vl. Unitário]] -> 53.942705 | F13: =VLOOKUP(TabelaTianguá[[#This Row],[Código+Produto]],Base!A:C,3,0) -> carne de sol mp | G13: =VLOOKUP(A13,Base!A:D,4,0) -> CARNES BOVINAS | I13: PEIXES E FRUTOS DO MAR | J13: salmao mp | K13: KG | L13: 6 | M13: 62.9 | N13: 377.4
A14: 429-carne de sol mp | B14: KG | C14: 0.9 | D14: 46.9067 | E14: =TabelaTianguá[[#This Row],[Qtde]]*TabelaTianguá[[#This Row],[Vl. Unitário]] -> 42.21603 | F14: =VLOOKUP(TabelaTianguá[[#This Row],[Código+Produto]],Base!A:C,3,0) -> carne de sol mp | G14: =VLOOKUP(A14,Base!A:D,4,0) -> CARNES BOVINAS
A15: 429-carne de sol mp | B15: KG | C15: 1.95 | D15: 46.9067 | E15: =TabelaTianguá[[#This Row],[Qtde]]*TabelaTianguá[[#This Row],[Vl. Unitário]] -> 91.468065 | F15: =VLOOKUP(TabelaTianguá[[#This Row],[Código+Produto]],Base!A:C,3,0) -> carne de sol mp | G15: =VLOOKUP(A15,Base!A:D,4,0) -> CARNES BOVINAS | I15: FRANGOS E DERIVADOS | J15: file de peito de frango mp | K15: KG | L15: 153.5 | M15: 17.6551 | N15: 2691.36
A16: 429-carne de sol mp | B16: KG | C16: 1.3 | D16: 46.9067 | E16: =TabelaTianguá[[#This Row],[Qtde]]*TabelaTianguá[[#This Row],[Vl. Unitário]] -> 60.97871 | F16: =VLOOKUP(TabelaTianguá[[#This Row],[Código+Produto]],Base!A:C,3,0) -> carne de sol mp | G16: =VLOOKUP(A16,Base!A:D,4,0) -> CARNES BOVINAS | I16: FRANGOS E DERIVADOS | J16: frango inteiro mp | K16: KG | L16: 16.6 | M16: 9.9708 | N16: 165.51528
A17: 430-contra file mp | B17: KG | C17: 16.1 | D17: 42.89 | E17: =TabelaTianguá[[#This Row],[Qtde]]*TabelaTianguá[[#This Row],[Vl. Unitário]] -> 690.529 | F17: =VLOOKUP(TabelaTianguá[[#This Row],[Código+Produto]],Base!A:C,3,0) -> contra file mp | G17: =VLOOKUP(A17,Base!A:D,4,0) -> CARNES BOVINAS | I17: FRANGOS E DERIVADOS | J17: coxa e sobrecoxa mp | K17: KG | L17: 10.8 | M17: 9.08985 | N17: 97.99047
A18: 430-contra file mp | B18: KG | C18: 23.74 | D18: 42.89 | E18: =TabelaTianguá[[#This Row],[Qtde]]*TabelaTianguá[[#This Row],[Vl. Unitário]] -> 1018.2086 | F18: =VLOOKUP(TabelaTianguá[[#This Row],[Código+Produto]],Base!A:C,3,0) -> contra file mp | G18: =VLOOKUP(A18,Base!A:D,4,0) -> CARNES BOVINAS
A19: 430-contra file mp | B19: KG | C19: 9.25 | D19: 42.89 | E19: =TabelaTianguá[[#This Row],[Qtde]]*TabelaTianguá[[#This Row],[Vl. Unitário]] -> 396.7325 | F19: =VLOOKUP(TabelaTianguá[[#This Row],[Código+Produto]],Base!A:C,3,0) -> contra file mp | G19: =VLOOKUP(A19,Base!A:D,4,0) -> CARNES BOVINAS | I19: CONGELADOS | J19: batata pre frita mp | K19: KG | L19: 232 | M19: 12.148147 | N19: 2813.5068
A20: 430-contra file mp | B20: KG | C20: 22.458 | D20: 39 | E20: =TabelaTianguá[[#This Row],[Qtde]]*TabelaTianguá[[#This Row],[Vl. Unitário]] -> 875.862 | F20: =VLOOKUP(TabelaTianguá[[#This Row],[Código+Produto]],Base!A:C,3,0) -> contra file mp | G20: =VLOOKUP(A20,Base!A:D,4,0) -> CARNES BOVINAS
A21: 430-contra file mp | B21: KG | C21: 10.15 | D21: 41.89 | E21: =TabelaTianguá[[#This Row],[Qtde]]*TabelaTianguá[[#This Row],[Vl. Unitário]] -> 425.1835 | F21: =VLOOKUP(TabelaTianguá[[#This Row],[Código+Produto]],Base!A:C,3,0) -> contra file mp | G21: =VLOOKUP(A21,Base!A:D,4,0) -> CARNES BOVINAS | I21: SUINOS E DERIVADOS | J21: bacon mp | K21: KG | L21: 49.73 | M21: 23.675486 | N21: 1182.6167
A22: 430-contra file mp | B22: KG | C22: 23.14 | D22: 41.89 | E22: =TabelaTianguá[[#This Row],[Qtde]]*TabelaTianguá[[#This Row],[Vl. Unitário]] -> 969.3346 | F22: =VLOOKUP(TabelaTianguá[[#This Row],[Código+Produto]],Base!A:C,3,0) -> contra file mp | G22: =VLOOKUP(A22,Base!A:D,4,0) -> CARNES BOVINAS | I22: SUINOS E DERIVADOS | J22: carne suina mp | K22: KG | L22: 62.9 | M22: 16.5701 | N22: 1042.2593
A23: 430-contra file mp | B23: KG | C23: 14.9 | D23: 41.89 | E23: =TabelaTianguá[[#This Row],[Qtde]]*TabelaTianguá[[#This Row],[Vl. Unitário]] -> 624.161 | F23: =VLOOKUP(TabelaTianguá[[#This Row],[Código+Produto]],Base!A:C,3,0) -> contra file mp | G23: =VLOOKUP(A23,Base!A:D,4,0) -> CARNES BOVINAS | I23: SUINOS E DERIVADOS | J23: costela suina mp | K23: KG | L23: 12.7 | M23: 19.51 | N23: 247.777
A24: 430-contra file mp | B24: KG | C24: 14.8 | D24: 41.89 | E24: =TabelaTianguá[[#This Row],[Qtde]]*TabelaTianguá[[#This Row],[Vl. Unitário]] -> 619.972 | F24: =VLOOKUP(TabelaTianguá[[#This Row],[Código+Produto]],Base!A:C,3,0) -> contra file mp | G24: =VLOOKUP(A24,Base!A:D,4,0) -> CARNES BOVINAS
A25: 430-contra file mp | B25: KG | C25: 17 | D25: 41 | E25: =TabelaTianguá[[#This Row],[Qtde]]*TabelaTianguá[[#This Row],[Vl. Unitário]] -> 697 | F25: =VLOOKUP(TabelaTianguá[[#This Row],[Código+Produto]],Base!A:C,3,0) -> contra file mp | G25: =VLOOKUP(A25,Base!A:D,4,0) -> CARNES BOVINAS | I25: LATICINIOS | J25: queijo mussarela mp | K25: KG | L25: 29.24 | M25: 31.19406 | N25: 912.24383
A26: 430-contra file mp | B26: KG | C26: 25.3 | D26: 41 | E26: =TabelaTianguá[[#This Row],[Qtde]]*TabelaTianguá[[#This Row],[Vl. Unitário]] -> 1037.3 | F26: =VLOOKUP(TabelaTianguá[[#This Row],[Código+Produto]],Base!A:C,3,0) -> contra file mp | G26: =VLOOKUP(A26,Base!A:D,4,0) -> CARNES BOVINAS | I26: LATICINIOS | J26: leite mp | K26: LT | L26: 209 | M26: 3.5 | N26: 731.5
A27: 430-contra file mp | B27: KG | C27: 15.4 | D27: 41 | E27: =TabelaTianguá[[#This Row],[Qtde]]*TabelaTianguá[[#This Row],[Vl. Unitário]] -> 631.4 | F27: =VLOOKUP(TabelaTianguá[[#This Row],[Código+Produto]],Base!A:C,3,0) -> contra file mp | G27: =VLOOKUP(A27,Base!A:D,4,0) -> CARNES BOVINAS | I27: LATICINIOS | J27: queijo coalho mp | K27: KG | L27: 20.4 | M27: 22.68945 | N27: 467.18143
A28: 430-contra file mp | B28: KG | C28: 8.4 | D28: 41 | E28: =TabelaTianguá[[#This Row],[Qtde]]*TabelaTianguá[[#This Row],[Vl. Unitário]] -> 344.4 | F28: =VLOOKUP(TabelaTianguá[[#This Row],[Código+Produto]],Base!A:C,3,0) -> contra file mp | G28: =VLOOKUP(A28,Base!A:D,4,0) -> CARNES BOVINAS | I28: LATICINIOS | J28: margarina mp | K28: KG | L28: 14 | M28: 8.31 | N28: 116.34
A29: 430-contra file mp | B29: KG | C29: 11 | D29: 39.89 | E29: =TabelaTianguá[[#This Row],[Qtde]]*TabelaTianguá[[#This Row],[Vl. Unitário]] -> 438.79 | F29: =VLOOKUP(TabelaTianguá[[#This Row],[Código+Produto]],Base!A:C,3,0) -> contra file mp | G29: =VLOOKUP(A29,Base!A:D,4,0) -> CARNES BOVINAS
A30: 430-contra file mp | B30: KG | C30: 17.5 | D30: 39.89 | E30: =TabelaTianguá[[#This Row],[Qtde]]*TabelaTianguá[[#This Row],[Vl. Unitário]] -> 698.075 | F30: =VLOOKUP(TabelaTianguá[[#This Row],[Código+Produto]],Base!A:C,3,0) -> contra file mp | G30: =VLOOKUP(A30,Base!A:D,4,0) -> CARNES BOVINAS | I30: SECOS E MERCEARIA | J30: maionese mp | K30: KG | L30: 50.4 | M30: 10.721633 | N30: 540.37032
A31: 430-contra file mp | B31: KG | C31: 17 | D31: 39 | E31: =TabelaTianguá[[#This Row],[Qtde]]*TabelaTianguá[[#This Row],[Vl. Unitário]] -> 663 | F31: =VLOOKUP(TabelaTianguá[[#This Row],[Código+Produto]],Base!A:C,3,0) -> contra file mp | G31: =VLOOKUP(A31,Base!A:D,4,0) -> CARNES BOVINAS | I31: SECOS E MERCEARIA | J31: feijao branco mp | K31: KG | L31: 50.1 | M31: 6.5 | N31: 325.65
A32: 432-file mignon mp | B32: KG | C32: 5.45 | D32: 65 | E32: =TabelaTianguá[[#This Row],[Qtde]]*TabelaTianguá[[#This Row],[Vl. Unitário]] -> 354.25 | F32: =VLOOKUP(TabelaTianguá[[#This Row],[Código+Produto]],Base!A:C,3,0) -> file mignon mp | G32: =VLOOKUP(A32,Base!A:D,4,0) -> CARNES BOVINAS | I32: SECOS E MERCEARIA | J32: arroz parboilizado mp | K32: KG | L32: 80 | M32: 3.8 | N32: 304.5
A33: 432-file mignon mp | B33: KG | C33: 5.35 | D33: 65 | E33: =TabelaTianguá[[#This Row],[Qtde]]*TabelaTianguá[[#This Row],[Vl. Unitário]] -> 347.75 | F33: =VLOOKUP(TabelaTianguá[[#This Row],[Código+Produto]],Base!A:C,3,0) -> file mignon mp | G33: =VLOOKUP(A33,Base!A:D,4,0) -> CARNES BOVINAS | I33: SECOS E MERCEARIA | J33: creme culinario mp | K33: KG | L33: 8 | M33: 12.634733 | N33: 101.9884
A34: 432-file mignon mp | B34: KG | C34: 11.5 | D34: 65 | E34: =TabelaTianguá[[#This Row],[Qtde]]*TabelaTianguá[[#This Row],[Vl. Unitário]] -> 747.5 | F34: =VLOOKUP(TabelaTianguá[[#This Row],[Código+Produto]],Base!A:C,3,0) -> file mignon mp | G34: =VLOOKUP(A34,Base!A:D,4,0) -> CARNES BOVINAS | I34: SECOS E MERCEARIA | J34: molho de tomate mp | K34: KG | L34: 12.5 | M34: 8 | N34: 100
A35: 432-file mignon mp | B35: KG | C35: 4.1 | D35: 65 | E35: =TabelaTianguá[[#This Row],[Qtde]]*TabelaTianguá[[#This Row],[Vl. Unitário]] -> 266.5 | F35: =VLOOKUP(TabelaTianguá[[#This Row],[Código+Produto]],Base!A:C,3,0) -> file mignon mp | G35: =VLOOKUP(A35,Base!A:D,4,0) -> CARNES BOVINAS | I35: SECOS E MERCEARIA | J35: farinha de rosca mp | K35: KG | L35: 14.15 | M35: 7 | N35: 99.05
A36: 432-file mignon mp | B36: KG | C36: 5 | D36: 64.9902 | E36: =TabelaTianguá[[#This Row],[Qtde]]*TabelaTianguá[[#This Row],[Vl. Unitário]] -> 324.951 | F36: =VLOOKUP(TabelaTianguá[[#This Row],[Código+Produto]],Base!A:C,3,0) -> file mignon mp | G36: =VLOOKUP(A36,Base!A:D,4,0) -> CARNES BOVINAS | I36: SECOS E MERCEARIA | J36: ketchup mp | K36: KG | L36: 6.8 | M36: 7.0592 | N36: 48.00256
A37: 432-file mignon mp | B37: KG | C37: 2.5 | D37: 64.9902 | E37: =TabelaTianguá[[#This Row],[Qtde]]*TabelaTianguá[[#This Row],[Vl. Unitário]] -> 162.4755 | F37: =VLOOKUP(TabelaTianguá[[#This Row],[Código+Produto]],Base!A:C,3,0) -> file mignon mp | G37: =VLOOKUP(A37,Base!A:D,4,0) -> CARNES BOVINAS | I37: SECOS E MERCEARIA | J37: macarrao espaguete mp | K37: 400G | L37: 14 | M37: 2.99 | N37: 41.86
A38: 432-file mignon mp | B38: KG | C38: 1.65 | D38: 64.9902 | E38: =TabelaTianguá[[#This Row],[Qtde]]*TabelaTianguá[[#This Row],[Vl. Unitário]] -> 107.23383 | F38: =VLOOKUP(TabelaTianguá[[#This Row],[Código+Produto]],Base!A:C,3,0) -> file mignon mp | G38: =VLOOKUP(A38,Base!A:D,4,0) -> CARNES BOVINAS | I38: SECOS E MERCEARIA | J38: arroz branco mp | K38: KG | L38: 9 | M38: 4.57 | N38: 41.13
A39: 432-file mignon mp | B39: KG | C39: 2.65 | D39: 64.9902 | E39: =TabelaTianguá[[#This Row],[Qtde]]*TabelaTianguá[[#This Row],[Vl. Unitário]] -> 172.22403 | F39: =VLOOKUP(TabelaTianguá[[#This Row],[Código+Produto]],Base!A:C,3,0) -> file mignon mp | G39: =VLOOKUP(A39,Base!A:D,4,0) -> CARNES BOVINAS | I39: SECOS E MERCEARIA | J39: vinagre mp | K39: 500ML | L39: 12 | M39: 1.46 | N39: 17.52
A40: 432-file mignon mp | B40: KG | C40: 2.7 | D40: 65 | E40: =TabelaTianguá[[#This Row],[Qtde]]*TabelaTianguá[[#This Row],[Vl. Unitário]] -> 175.5 | F40: =VLOOKUP(TabelaTianguá[[#This Row],[Código+Produto]],Base!A:C,3,0) -> file mignon mp | G40: =VLOOKUP(A40,Base!A:D,4,0) -> CARNES BOVINAS | I40: SECOS E MERCEARIA | J40: acucar mp | K40: KG | L40: 5 | M40: 3 | N40: 15
A41: 432-file mignon mp | B41: KG | C41: 2.3 | D41: 65 | E41: =TabelaTianguá[[#This Row],[Qtde]]*TabelaTianguá[[#This Row],[Vl. Unitário]] -> 149.5 | F41: =VLOOKUP(TabelaTianguá[[#This Row],[Código+Produto]],Base!A:C,3,0) -> file mignon mp | G41: =VLOOKUP(A41,Base!A:D,4,0) -> CARNES BOVINAS
A42: 432-file mignon mp | B42: KG | C42: 3.15 | D42: 65 | E42: =TabelaTianguá[[#This Row],[Qtde]]*TabelaTianguá[[#This Row],[Vl. Unitário]] -> 204.75 | F42: =VLOOKUP(TabelaTianguá[[#This Row],[Código+Produto]],Base!A:C,3,0) -> file mignon mp | G42: =VLOOKUP(A42,Base!A:D,4,0) -> CARNES BOVINAS | I42: EMBUTIDOS | J42: linguica suina mp | K42: KG | L42: 70 | M42: 17.624 | N42: 1239.25
...

Sheet Base
A1: Produto | B1: Código | C1: Descrição | D1: Grupo
A2: =B2&"-"&C2 -> 1-AGUA SEM GAS 500ML | B2: 1 | C2: AGUA SEM GAS 500ML | D2: AGUAS
A3: =B3&"-"&C3 -> 2-AGUA SEM GAS 1,5L | B3: 2 | C3: AGUA SEM GAS 1,5L | D3: AGUAS
A4: =B4&"-"&C4 -> 3-AGUA COM GAS 500ML | B4: 3 | C4: AGUA COM GAS 500ML | D4: AGUAS
A5: =B5&"-"&C5 -> 4-AGUA DE COCO | B5: 4 | C5: AGUA DE COCO | D5: AGUAS
A6: =B6&"-"&C6 -> 5-AGUA TONICA ANTARCTICA 350ML | B6: 5 | C6: AGUA TONICA ANTARCTICA 350ML | D6: AGUAS
A7: =B7&"-"&C7 -> 6-AGUA TONICA SCHWEPPES 350ML | B7: 6 | C7: AGUA TONICA SCHWEPPES 350ML | D7: AGUAS
A8: =B8&"-"&C8 -> 7-SUCO LARANJA 1100ML | B8: 7 | C8: SUCO LARANJA 1100ML | D8: SUCOS NATURAIS
A9: =B9&"-"&C9 -> 8-SUCO LARANJA 750ML | B9: 8 | C9: SUCO LARANJA 750ML | D9: SUCOS NATURAIS
A10: =B10&"-"&C10 -> 9-SUCO LARANJA 350ML | B10: 9 | C10: SUCO LARANJA 350ML | D10: SUCOS NATURAIS
A11: =B11&"-"&C11 -> 10-SUCO ABACAXI 1100ML | B11: 10 | C11: SUCO ABACAXI 1100ML | D11: SUCOS NATURAIS
A12: =B12&"-"&C12 -> 11-SUCO ABACAXI 750ML | B12: 11 | C12: SUCO ABACAXI 750ML | D12: SUCOS NATURAIS
A13: =B13&"-"&C13 -> 12-SUCO ABACAXI 350ML | B13: 12 | C13: SUCO ABACAXI 350ML | D13: SUCOS NATURAIS
... A1015: =B1015&"-"&C1015 -> 1034-CORONA ZERO LN 300ML | B1015: 1034 | C1015: CORONA ZERO LN 300ML | D1015: CERVEJAS ZERO ALCOOL
A1016: 1041-STELLA ARTOIS PURE G LN 330ML | B1016: 1041 | C1016: STELLA ARTOIS PURE G LN 330ML | D1016: CERVEJAS
A1017: 1073-azeitona mp | B1017: 1073 | C1017: AZEITONA | D1017: SECOS E MERCEARIA
A1018: 1090-capa de contra file mp | B1018: 1090 | C1018: capa de contra file mp | D1018: CARNES BOVINAS
